Workbook

Sheet Master Data All
A1: Timestamp | B1: Tanggal Pengajuan | C1: Nama Pemohon Kredit | D1: Nomor Telepon Pemohon Kredit | E1: Pekerjaan Pemohon Kredit | F1: Penghasilan Bulanan Pemohon Kredit | G1: Apakah ada NPWP | H1: Total limit yang didapatkan | I1: Status pengajuan | J1: Kendala saat pengajuan | K1: Upload bukti pengajuan | L1: Area | M1: Tipe HP VIVO yang diambil konsumen | N1: Sator Area Kupang | O1: Sator Area Sumba | P1: Nama Promotor | Q1: Nama Promotor | R1: Nama Promotor | S1: Nama Promotor | T1: Nama Promotor | U1: Nama Promotor | V1: Nama Promotor | W1: Nama Promotor | X1: Nama Promotor | Y1: Column 25 | Z1: Column 26 | AA1: Column 27
A2: 45897.586 | C2: TRIYUANI REINNAMAH | D2: +62 856-8309-785 | E2: SELES | F2: 2JT | G2: Tidak ada | H2: 0 | I2: Reject | J2: - | K2: https://drive.google.com/open?id=1v-cfYDTQqA-R55g32y0mMpJ2Xden8dLJ | L2: Kupang Kota | Q2: DEMARISTI S H FENI
A3: 45897.593 | C3: Adeltrudis hoar | D3: +62 812-5358-4502 | E3: Wiraswasta | F3: 4500000 | G3: Tidak ada | H3: 7.000.000 | I3: Acc | J3: Tidak ada | K3: https://drive.google.com/open?id=1EEnKnPzj4BU5jvvOVf4vlRw3IDTngY6j | L3: Kupang Kota | M3: Y400 | Q3: EMPI FRANGKI LIEM
A4: 45897.594 | C4: Imelda febriana magdalena lelik | D4: +62 857-3874-4175 | E4: Wiraswasta | F4: 4 | G4: Tidak ada | H4: 4.300.000 | I4: Reject | J4: Tidak ada | K4: https://drive.google.com/open?id=1bd8ocKNWbiY1qE9xEiaaeCRMM5-RAEM1 | L4: Kupang Kota | Q4: EMPI FRANGKI LIEM
A5: 45897.606 | C5: Pricsa Fita Chandra Ayu Defretes | D5: +62 877-1590-0008 | E5: Pegawai Swasta | F5: 8-9jt | G5: Ada | H5: - | I5: Reject | J5: - | K5: https://drive.google.com/open?id=1KMM1glijqISnf_J2s7Chw-PKVClwBDzo | L5: Kupang Kota | Q5: YOHANA NOVIANA MARIANA GAA
A6: 45897.639 | C6: Romana Pati | D6: 081230387876 | E6: Pegawai Swasta | F6: 3.500.000 | G6: Tidak ada | H6: Tidak Ada | I6: Reject | J6: Tidak Ada | K6: https://drive.google.com/open?id=1Umo2LS8svJPAB-3fFIgZVewcMcwe4OY8 | L6: Kupang Kota | Q6: PATRIANI MENGI ULY
A7: 45897.649 | C7: Derison lot saluk | D7: 085959344060 | E7: Pemilik pangkas rambut | F7: 3.500.000 | G7: Tidak ada | H7: Tidak ada | I7: Reject | J7: Tidak ada | K7: https://drive.google.com/open?id=1If_zKQvOp5junZ0JAq22Ln94GqwOTGvG | L7: Kupang Kota | Q7: NOVANTRY RUTHANIA NAFFIE
A8: 45897.651 | C8: Melani sara betty | D8: 081998343074 | E8: Online shop butik | F8: 2.500.000 | G8: Tidak ada | H8: Tidak ada | I8: Reject | J8: Tidak dapat limite | K8: https://drive.google.com/open?id=1wDAR-QAoBMP1AFr8tN4HQP_snrdSDpFY | L8: Kupang Kota | Q8: NOVANTRY RUTHANIA NAFFIE
A9: 45897.652 | C9: Novita Mea Ikun Pires | D9: 081236833055 | E9: Pegawai Swasta | F9: 3-4jt | G9: Tidak ada | H9: - | I9: Reject | J9: - | K9: https://drive.google.com/open?id=1zMbcG1lRzhverF7lB1BtbGfPrsd_cgeH | L9: Kupang Kota | Q9: YOHANA NOVIANA MARIANA GAA
A10: 45897.692 | C10: ALEXA DEHOOG | D10: 082217974397 | E10: KARYAWAN SWASTA | F10: 3JT | G10: Tidak ada | H10: 3jt | I10: Acc | J10: - | K10: https://drive.google.com/open?id=1rEp7-vGA12-eDqwR9-3guAOPU3x17IRj | L10: Kupang Kota | M10: Y400 | Q10: DEMARISTI S H FENI
A11: 45897.754 | C11: Maria Inggrid Dogho | D11: 082236726681 | E11: GURU TK PERTIWI | F11: 4.600.000 | G11: Ada | H11: 3.000.000 | I11: Dapat Limit Cuma Dp kurang, masih pulang Bicara Sama Suami Soal Dp | J11: Tidak Ada | K11: https://drive.google.com/open?id=1rRiHChF6lS8XOFDgK-X5qiGX5u3XwASD | L11: Kupang Kota | Q11: YOHANIS TIPNONI
A12: 45897.779 | C12: DOMINGGUS CRISTIAN LEDE | D12: 0811 | E12: Dinas lingkungan dan kebersihan kota kupang | F12: 4.100.000 | G12: Tidak ada | H12: 0 | I12: Reject | J12: tidak ad | K12: https://drive.google.com/open?id=1eDTdhgf1M0aYwBhJdujtSOP_7GChk5Hy | L12: Kupang Kota | Q12: YASINTHA MBU
A13: 45897.78 | C13: Diniati kiki | D13: 082121166521 | E13: Usaha kios | F13: 5.600.000 | G13: Tidak ada | H13: 0 | I13: Sistem masih bermasalah | J13: Nama toko tidak sesuai | K13: https://drive.google.com/open?id=1lv3v6LtVw6JeFo3ACOX3n4QmsdHKoKtG | L13: Kupang Kota | Q13: AINI RAHMATINI NATALIA MOESTAKIM
A14: 45897.781 | C14: Rivaldo nunes | D14: 081237415440 | E14: Wiraswasta | F14: 6.000.000 | G14: Tidak ada | H14: 0 | I14: Sistem bermasalah | J14: Nama toko tidak sesuai | K14: https://drive.google.com/open?id=1B1MwnAjmIQ53ybBXzWRc1E4R86t-OEns | L14: Kupang Kota | Q14: AINI RAHMATINI NATALIA MOESTAKIM
A15: 45897.8 | C15: Anis | D15: 12345678 | E15: Tukang | F15: 2000000 | G15: Tidak ada | H15: 0 | I15: Reject | J15: - | K15: https://drive.google.com/open?id=1szhhvdFusPgOAt9Fcr_gIiUaQ5wUFGrv | L15: Kabupaten | Q15: Tes
A16: 45897.809 | C16: Agus | D16: 082147979471 | E16: Wiraswasta | F16: 10 | G16: Tidak ada | H16: 0 | I16: Reject | J16: Pas | K16: https://drive.google.com/open?id=1w6RCkrMHlBINEIPqpDZDfYISau1-VoZJ | L16: Kabupaten | Q16: Tes
A17: 45897.835 | C17: Maria goretitokan | D17: 081247920167 | E17: Anggota DPRD kabupaten kupang | F17: 7.000.000 | G17: Ada | H17: 0 | I17: Sistem eror | J17: Toko tidak sesuai | K17: https://drive.google.com/open?id=1x8rpntpmgkMZaHVEfyerFJmBfWOQBPUT | L17: Kupang Kota | Q17: AINI RAHMATINI NATALIA MOESTAKIM
A18: 45897.837 | C18: Rangga Djara | D18: 085119992958 | E18: Nelayan | F18: 1.500.000 | G18: Tidak ada | H18: 0 | I18: Reject | J18: - | K18: https://drive.google.com/open?id=1AGXZte4Yb-yCOjMBRQ831OFnxpEHY3m- | L18: Kupang Kota | Q18: FERI ELI KURNIAWAN
A19: 45898.38 | C19: RAFAEL RUNESI | D19: 085338580958 | E19: WIRASWASTA | F19: 4.200.000 | G19: Tidak ada | H19: 0 | I19: Reject | K19: https://drive.google.com/open?id=1Vd0fsJFiBXGfYIHSycubBlH2BpXH_AgF | L19: Kupang Kota | Q19: YASINTHA MBU
A20: 45898.499 | C20: Yavet hati | D20: 082146992105 | E20: Swasta | F20: 5.100.000 | G20: Tidak ada | H20: 7.000.000 | I20: Acc | J20: Tidak ada | K20: https://drive.google.com/open?id=1EJxzoNsNgAbP-nOggCWumQcgyShsv5dU | L20: Kupang Kota | M20: Y400 | Q20: YASINTHA MBU
A21: 45898.571 | C21: Maria Bella Savira Mbao | D21: 081236922745 | E21: Alfa Mart | F21: 3.700.000 | G21: Tidak ada | H21: Tidak ada | I21: Reject | J21: Tidak Dapat Limit | K21: https://drive.google.com/open?id=14ehdJhB5qvnEMFUTjcuAXJiNVSTDhWo- | L21: Kupang Kota | Q21: YOHANIS TIPNONI
A22: 45898.659 | C22: Yuni yulianer suni | D22: 081529259284 | E22: Jaga warung | F22: 2.000.000 | G22: Tidak ada | H22: Tdk dpt limited | I22: Reject | J22: Toko di Sistem tidak sesuai | K22: https://drive.google.com/open?id=10JmHEAWciNGbbewtF8pGd0yImG8FBKrW | L22: Kupang Kota | M22: Y400 | Q22: WARDIA
A23: 45898.676 | C23: IBRAHIM KUSUMA | D23: 081214553021 | E23: Nelayan | F23: 5.700.000 | G23: Tidak ada | H23: 0 | I23: belum dapat limit | J23: belum dapat limit | K23: https://drive.google.com/open?id=16aYa7bofZteV9nGu-VIcZuA-DHA9bSfL | L23: Kupang Kota | M23: Y400 | Q23: YASINTHA MBU
A24: 45898.792 | C24: Adriana luan | D24: 081337998055 | E24: ASN | F24: 5.700.000 | G24: Tidak ada | H24: 7.0000.000 | I24: Acc | J24: tidak ada | K24: https://drive.google.com/open?id=1Zlb06HvHIArpia6RmZLkOfeL7kHkk9Pc | L24: Kupang Kota | M24: V50 LITE | Q24: YASINTHA MBU
A25: 45898.836 | C25: Richi | D25: 082334922953 | E25: Dinas Kesehatan | F25: 3000000 | G25: Tidak ada | H25: 0 | I25: Tidak dapat limit | J25: Pengajuan Kadaluarsa | K25: https://drive.google.com/open?id=1Rfjpfn8wH63-dlGpgFrzF9P681ai2uZ2 | L25: Kupang Kota | M25: Y400 | Q25: SELVINCE BAKO
A26: 45898.865 | C26: Meryanti foeh | D26: - | E26: Wiraswasta | F26: 2jt | G26: Tidak ada | H26: 0 | I26: Reject | J26: Tidak dapat limit | K26: https://drive.google.com/open?id=1O66NvvEF15ofHKvQeyXS1DF8cH1jTH3X | L26: Kupang Kota | M26: Y400 | Q26: SKOLASTIKA B TAUNAES
A27: 45898.865 | C27: Yohana | D27: 08123608690 | E27: Wiraswasta | F27: 0 | G27: Tidak ada | H27: 0 | I27: Tidak dapt limit | J27: Pengajuan Kadaluarsa | K27: https://drive.google.com/open?id=1wmofbO6IAaXPJ9bz1b1yVIYSyu8W8-hx | L27: Kupang Kota | M27: Lain nya... | Q27: SELVINCE BAKO
A28: 45898.867 | C28: Marcia Estin Wathun ximenes | D28: 082298258277 | E28: Wiraswasta | F28: 5.700.000 | G28: Tidak ada | H28: Tidak ada | I28: Tidak dapat limit | J28: Tidak dapat limit | K28: https://drive.google.com/open?id=1B7iDB3xt_eSksY-i5-wrRq3YFS99U7OZ | L28: Kupang Kota | M28: Y400 | Q28: YOHANIS TIPNONI
A29: 45898.867 | C29: Fory Yani F. Tasi | D29: - | E29: Wiraswasta | F29: 2.500.000 | G29: Tidak ada | H29: 0 | I29: Reject | J29: Tidak dapat limit | K29: https://drive.google.com/open?id=1VnURt4QYqFB5k4ks6_7wFARP9SrSrR0g | L29: Kupang Kota | M29: Y400 | Q29: SKOLASTIKA B TAUNAES
A30: 45898.87 | C30: Marsela Sinlaeloe | D30: 082266021692 | E30: Karyawan | F30: 3.400.000 | G30: Tidak ada | H30: Tidak ada | I30: Tidak ada limit | J30: Tidak ada limit | K30: https://drive.google.com/open?id=1_iU8TfcTWtawo4DfXWqrofBtWftHGU1R | L30: Kabupaten | M30: Y400 | Q30: YOHANIS TIPNONI
A31: 45898.87 | C31: Febrianthy Elisabet Nau | D31: 082145568229 | E31: Spg | F31: 1.5 | G31: Tidak ada | H31: 0 | I31: Reject | J31: Tidak dapat limit | K31: https://drive.google.com/open?id=1mGlvXVrtof0kjaMI-wLLPPPmFGUXhjjG | L31: Kupang Kota | M31: Y400 | Q31: FEBRIANTHY ELISABET NA'U
A32: 45898.872 | C32: Aldy pratama johanis lada | D32: 0822-3682-3894 | E32: WO | F32: 2.500.000 | G32: Tidak ada | H32: 0 | I32: Reject | J32: Tidak dapat limit | K32: https://drive.google.com/open?id=1BLCTQ1WZqB_lfm5MzW3Webbdxq1DLpiM | L32: Kupang Kota | M32: Y400 | Q32: FEBRIANTHY ELISABET NA'U
A33: 45899.528 | C33: Hendriani dethan | D33: 081993939068 | E33: Pegawai Negeri Sipil (PNS) | F33: 4000000 | G33: Ada | H33: 5000000 | I33: ACC | K33: https://drive.google.com/open?id=1ICVUf6i_l2qKBjqN9oTwRJrBur9pv_LH, https://drive.google.com/open?id=1-YAnP6KvVlEgZaxLAv-jfl02i31jCkLh | L33: Kupang | M33: Y400 series | N33: TUTOR ANDRI RUDOLOF ELI MANAFE | O33: TUTOR KUSMYATI KILIMANDU | P33: KESIA NATALIA I. BENU | Q33: MARNITHA JUWIKE TIMORATI RUNESI
A34: 45899.572 | C34: Dortia Ndoen | D34: 81284633899 | E34: Pegawai Swasta | F34: 3000000 | G34: Tidak ada | I34: No Limit | J34: Tidak ada limit | K34: https://drive.google.com/open?id=1yahZ4lUxomfSdnZWX2rRVxQ5bcrk4Nf3 | L34: Kupang | N34: TUTOR ANDRI RUDOLOF ELI MANAFE | R34: YOHANA NOVIANA MARIANA GAA
A35: 45899.619 | C35: Silfa Koa | D35: 082178863126 | E35: Pengusaha | F35: 2000000 | G35: Tidak ada | H35: 5000000 | I35: ACC | K35: https://drive.google.com/open?id=1xUVs50VlYdxW5lHJ-y539dikFZzvQ5Tq | L35: Kupang | M35: Y400 series | N35: TUTOR HERY YULIUS DILLAK | W35: MERDA PUTRI BUNGSU KENAT
A36: 45899.775 | C36: Bernadeta Ceunfin | D36: 085333096207 | E36: Wiraswasta | F36: 5000000 | G36: Tidak ada | H36: 7000000 | I36: ACC | K36: https://drive.google.com/open?id=18_Cmkd-ObaypTDAsME5KtYNzxXCn7v8a | L36: Kupang | M36: Y400 series | N36: TUTOR ANTONIO DE JANAIRO TOMASOEY | Q36: EMPI FRANGKI LIEM | S36: EMPI FRANGKI LIEM
A37: 45899.787 | C37: Yunita Elik | D37: 087744028620 | E37: Wiraswasta warung makan | F37: 4700000 | G37: Tidak ada | I37: No Limit | J37: No limit | K37: https://drive.google.com/open?id=1mSKe-BM6uoBOCyt1s-MldJnTbe4uvuso | L37: Kupang | N37: TUTOR ANTONIO DE JANAIRO TOMASOEY | Q37: YOHANIS TIPNONI | S37: YOHANIS TIPNONI
A38: 45899.812 | C38: Sendi M Halla | D38: 082266057704 | E38: Buruh | F38: 2000000 | G38: Tidak ada | I38: Belum disetujui | J38: Reject | K38: https://drive.google.com/open?id=1oxA0-wl-sGAvu8UV-IVLQmkUQzSb2kMi | L38: Kupang | N38: TUTOR ANTONIO DE JANAIRO TOMASOEY | Q38: NOVANTRY RUTHANIA NAFFIE | S38: NOVANTRY RUTHANIA NAFFIE
A39: 45899.826 | C39: 𝘚𝘦𝘯𝘥𝘪 𝘮𝘢𝘳𝘪𝘢𝘯𝘢 𝘩𝘢𝘭𝘭𝘢 | D39: 082266057704 | E39: Buruh | F39: 3000000 | G39: Tidak ada | I39: Belum disetujui | J39: Belum disetujui tidak dapat limite | K39: https://drive.google.com/open?id=1_CG7QP1-jHtth3yizcWkzi3TfUPbcU0u | L39: Kupang | N39: TUTOR ANTONIO DE JANAIRO TOMASOEY | Q39: NOVANTRY RUTHANIA NAFFIE | S39: NOVANTRY RUTHANIA NAFFIE
A40: 45899.828 | C40: RENIJUFTARI LOBO HUKI | D40: 081338255675 | E40: Pegawai Swasta | F40: 4500000 | G40: Tidak ada | H40: 19459000 | I40: ACC | K40: https://drive.google.com/open?id=1uTn6ojdkFMr4okLy-sFSZyuX5qGMG2m4, https://drive.google.com/open?id=1UZ5Q3xQnejGgBBSxoUyRZJ0yZ-BCNpAJ | L40: Kupang | M40: Y400 series | N40: TUTOR ANTONIO DE JANAIRO TOMASOEY | Q40: FERI ELI KURNIAWAN | S40: FERI ELI KURNIAWAN
...

Sheet Sheet21
A1: TANGGAL | B1: NAMA_PROMOTOR | C1: STATUS_PENGAJUAN | D1: TIPE_HP | E1: ID _TOKO | F1: SATOR | G1: TOKO | H1: AREA
A2: =IFERROR(__xludf.DUMMYFUNCTION("SORT({ QUERY('Master Data All'!A2:X37256, ""select A, P, I, M where P is not null"", 0); QUERY('Master Data All'!A2:X37256, ""select A, Q, I, M where Q is not null"", 0); QUERY('Master Data All'!A2:X37256, ""select A, R, I, M where R is not null"", 0);"&" QUERY('Master Data All'!A2:X37256, ""select A, S, I, M where S is not null"", 0); QUERY('Master Data All'!A2:X37256, ""select A, T, I, M where T is not null"", 0); QUERY('Master Data All'!A2:X37256, ""select A, U, I, M where U is not null"", 0); QUER"&"Y('Master Data All'!A2:X37256, ""select A, V, I, M where V is not null"", 0); QUERY('Master Data All'!A2:X37256, ""select A, W, I, M where W is not null"", 0); QUERY('Master Data All'!A2:X37256, ""select A, X, I, M where X is not null"", 0) }, 1, TRUE) "),45897.58597868056) -> 45897.586 | B2: =IFERROR(__xludf.DUMMYFUNCTION("""COMPUTED_VALUE"""),"DEMARISTI S H FENI") -> DEMARISTI S H FENI | C2: =IFERROR(__xludf.DUMMYFUNCTION("""COMPUTED_VALUE"""),"Reject") -> Reject | E2: {=IF(B2:B37256="", "", IFERROR(VLOOKUP(TRIM(B2:B37256), 'Database Promotor'!B:E, 4, FALSE), ""))} | F2: {=IF(B2:B37256="", "", IFERROR(VLOOKUP(TRIM(B2:B37256), 'Database Promotor'!B:E, 2, FALSE), ""))} | G2: {=IF(E2:E37256="", "", IFERROR(VLOOKUP(E2:E37256, 'Database Toko'!A:D, 2, FALSE), ""))} | H2: {=IF(E2:E37256="", "", IFERROR(VLOOKUP(E2:E37256, 'Database Toko'!A:D, 4, FALSE), ""))}
A3: =IFERROR(__xludf.DUMMYFUNCTION("""COMPUTED_VALUE"""),45897.59262289351) -> 45897.593 | B3: =IFERROR(__xludf.DUMMYFUNCTION("""COMPUTED_VALUE"""),"EMPI FRANGKI LIEM") -> EMPI FRANGKI LIEM | C3: =IFERROR(__xludf.DUMMYFUNCTION("""COMPUTED_VALUE"""),"Acc") -> Acc | D3: =IFERROR(__xludf.DUMMYFUNCTION("""COMPUTED_VALUE"""),"Y400") -> Y400 | E3: MCE001 | F3: TUTOR ANTONIO DE JANAIRO TOMASOEY | G3: MCELL | H3: KUPANG
A4: =IFERROR(__xludf.DUMMYFUNCTION("""COMPUTED_VALUE"""),45897.59448921296) -> 45897.594 | B4: =IFERROR(__xludf.DUMMYFUNCTION("""COMPUTED_VALUE"""),"EMPI FRANGKI LIEM") -> EMPI FRANGKI LIEM | C4: =IFERROR(__xludf.DUMMYFUNCTION("""COMPUTED_VALUE"""),"Reject") -> Reject | E4: MCE001 | F4: TUTOR ANTONIO DE JANAIRO TOMASOEY | G4: MCELL | H4: KUPANG
A5: =IFERROR(__xludf.DUMMYFUNCTION("""COMPUTED_VALUE"""),45897.60611929398) -> 45897.606 | B5: =IFERROR(__xludf.DUMMYFUNCTION("""COMPUTED_VALUE"""),"YOHANA NOVIANA MARIANA GAA") -> YOHANA NOVIANA MARIANA GAA | C5: =IFERROR(__xludf.DUMMYFUNCTION("""COMPUTED_VALUE"""),"Reject") -> Reject | E5: SPC007 | F5: TUTOR ANDRI RUDOLOF ELI MANAFE | G5: SPC PLATINUM | H5: KUPANG
A6: =IFERROR(__xludf.DUMMYFUNCTION("""COMPUTED_VALUE"""),45897.639471574075) -> 45897.639 | B6: =IFERROR(__xludf.DUMMYFUNCTION("""COMPUTED_VALUE"""),"PATRIANI MENGI ULY") -> PATRIANI MENGI ULY | C6: =IFERROR(__xludf.DUMMYFUNCTION("""COMPUTED_VALUE"""),"Reject") -> Reject | E6: SPC004 | F6: TUTOR ANDRI RUDOLOF ELI MANAFE | G6: SPC MASTER CELL | H6: KUPANG
A7: =IFERROR(__xludf.DUMMYFUNCTION("""COMPUTED_VALUE"""),45897.64885048611) -> 45897.649 | B7: =IFERROR(__xludf.DUMMYFUNCTION("""COMPUTED_VALUE"""),"NOVANTRY RUTHANIA NAFFIE") -> NOVANTRY RUTHANIA NAFFIE | C7: =IFERROR(__xludf.DUMMYFUNCTION("""COMPUTED_VALUE"""),"Reject") -> Reject | E7: MCE001 | F7: TUTOR ANTONIO DE JANAIRO TOMASOEY | G7: MCELL | H7: KUPANG
A8: =IFERROR(__xludf.DUMMYFUNCTION("""COMPUTED_VALUE"""),45897.65071901621) -> 45897.651 | B8: =IFERROR(__xludf.DUMMYFUNCTION("""COMPUTED_VALUE"""),"NOVANTRY RUTHANIA NAFFIE") -> NOVANTRY RUTHANIA NAFFIE | C8: =IFERROR(__xludf.DUMMYFUNCTION("""COMPUTED_VALUE"""),"Reject") -> Reject | E8: MCE001 | F8: TUTOR ANTONIO DE JANAIRO TOMASOEY | G8: MCELL | H8: KUPANG
A9: =IFERROR(__xludf.DUMMYFUNCTION("""COMPUTED_VALUE"""),45897.65229791666) -> 45897.652 | B9: =IFERROR(__xludf.DUMMYFUNCTION("""COMPUTED_VALUE"""),"YOHANA NOVIANA MARIANA GAA") -> YOHANA NOVIANA MARIANA GAA | C9: =IFERROR(__xludf.DUMMYFUNCTION("""COMPUTED_VALUE"""),"Reject") -> Reject | E9: SPC007 | F9: TUTOR ANDRI RUDOLOF ELI MANAFE | G9: SPC PLATINUM | H9: KUPANG
A10: =IFERROR(__xludf.DUMMYFUNCTION("""COMPUTED_VALUE"""),45897.69177612269) -> 45897.692 | B10: =IFERROR(__xludf.DUMMYFUNCTION("""COMPUTED_VALUE"""),"DEMARISTI S H FENI") -> DEMARISTI S H FENI | C10: =IFERROR(__xludf.DUMMYFUNCTION("""COMPUTED_VALUE"""),"Acc") -> Acc | D10: =IFERROR(__xludf.DUMMYFUNCTION("""COMPUTED_VALUE"""),"Y400") -> Y400
A11: =IFERROR(__xludf.DUMMYFUNCTION("""COMPUTED_VALUE"""),45897.75415983797) -> 45897.754 | B11: =IFERROR(__xludf.DUMMYFUNCTION("""COMPUTED_VALUE"""),"YOHANIS TIPNONI") -> YOHANIS TIPNONI | C11: =IFERROR(__xludf.DUMMYFUNCTION("""COMPUTED_VALUE"""),"Dapat Limit Cuma Dp kurang, masih pulang Bicara Sama Suami Soal Dp") -> Dapat Limit Cuma Dp kurang, masih pulang Bicara Sama Suami Soal Dp | E11: KIN001 | F11: TUTOR ANTONIO DE JANAIRO TOMASOEY | G11: KING CELL | H11: KUPANG
A12: =IFERROR(__xludf.DUMMYFUNCTION("""COMPUTED_VALUE"""),45897.77933287037) -> 45897.779 | B12: =IFERROR(__xludf.DUMMYFUNCTION("""COMPUTED_VALUE"""),"YASINTHA MBU") -> YASINTHA MBU | C12: =IFERROR(__xludf.DUMMYFUNCTION("""COMPUTED_VALUE"""),"Reject") -> Reject | E12: TER001 | F12: TUTOR ANTONIO DE JANAIRO TOMASOEY | G12: TERMINAL HP | H12: KUPANG
A13: =IFERROR(__xludf.DUMMYFUNCTION("""COMPUTED_VALUE"""),45897.77954232639) -> 45897.78 | B13: =IFERROR(__xludf.DUMMYFUNCTION("""COMPUTED_VALUE"""),"AINI RAHMATINI NATALIA MOESTAKIM") -> AINI RAHMATINI NATALIA MOESTAKIM | C13: =IFERROR(__xludf.DUMMYFUNCTION("""COMPUTED_VALUE"""),"Sistem masih bermasalah") -> Sistem masih bermasalah | E13: SPC006 | F13: TUTOR ANDRI RUDOLOF ELI MANAFE | G13: SPC OESAPA | H13: KUPANG
A14: =IFERROR(__xludf.DUMMYFUNCTION("""COMPUTED_VALUE"""),45897.78107916666) -> 45897.781 | B14: =IFERROR(__xludf.DUMMYFUNCTION("""COMPUTED_VALUE"""),"AINI RAHMATINI NATALIA MOESTAKIM") -> AINI RAHMATINI NATALIA MOESTAKIM | C14: =IFERROR(__xludf.DUMMYFUNCTION("""COMPUTED_VALUE"""),"Sistem bermasalah") -> Sistem bermasalah | E14: SPC006 | F14: TUTOR ANDRI RUDOLOF ELI MANAFE | G14: SPC OESAPA | H14: KUPANG
A15: =IFERROR(__xludf.DUMMYFUNCTION("""COMPUTED_VALUE"""),45897.80027759259) -> 45897.8 | B15: =IFERROR(__xludf.DUMMYFUNCTION("""COMPUTED_VALUE"""),"Tes") -> Tes | C15: =IFERROR(__xludf.DUMMYFUNCTION("""COMPUTED_VALUE"""),"Reject") -> Reject
A16: =IFERROR(__xludf.DUMMYFUNCTION("""COMPUTED_VALUE"""),45897.80897542824) -> 45897.809 | B16: =IFERROR(__xludf.DUMMYFUNCTION("""COMPUTED_VALUE"""),"Tes") -> Tes | C16: =IFERROR(__xludf.DUMMYFUNCTION("""COMPUTED_VALUE"""),"Reject") -> Reject
A17: =IFERROR(__xludf.DUMMYFUNCTION("""COMPUTED_VALUE"""),45897.835055891206) -> 45897.835 | B17: =IFERROR(__xludf.DUMMYFUNCTION("""COMPUTED_VALUE"""),"AINI RAHMATINI NATALIA MOESTAKIM") -> AINI RAHMATINI NATALIA MOESTAKIM | C17: =IFERROR(__xludf.DUMMYFUNCTION("""COMPUTED_VALUE"""),"Sistem eror") -> Sistem eror | E17: SPC006 | F17: TUTOR ANDRI RUDOLOF ELI MANAFE | G17: SPC OESAPA | H17: KUPANG
A18: =IFERROR(__xludf.DUMMYFUNCTION("""COMPUTED_VALUE"""),45897.83743508102) -> 45897.837 | B18: =IFERROR(__xludf.DUMMYFUNCTION("""COMPUTED_VALUE"""),"FERI ELI KURNIAWAN") -> FERI ELI KURNIAWAN | C18: =IFERROR(__xludf.DUMMYFUNCTION("""COMPUTED_VALUE"""),"Reject") -> Reject | E18: PLA001 | F18: TUTOR ANTONIO DE JANAIRO TOMASOEY | G18: PLANET GADGET | H18: KUPANG
A19: =IFERROR(__xludf.DUMMYFUNCTION("""COMPUTED_VALUE"""),45898.3801822338) -> 45898.38 | B19: =IFERROR(__xludf.DUMMYFUNCTION("""COMPUTED_VALUE"""),"YASINTHA MBU") -> YASINTHA MBU | C19: =IFERROR(__xludf.DUMMYFUNCTION("""COMPUTED_VALUE"""),"Reject") -> Reject | E19: TER001 | F19: TUTOR ANTONIO DE JANAIRO TOMASOEY | G19: TERMINAL HP | H19: KUPANG
A20: =IFERROR(__xludf.DUMMYFUNCTION("""COMPUTED_VALUE"""),45898.499299629635) -> 45898.499 | B20: =IFERROR(__xludf.DUMMYFUNCTION("""COMPUTED_VALUE"""),"YASINTHA MBU") -> YASINTHA MBU | C20: =IFERROR(__xludf.DUMMYFUNCTION("""COMPUTED_VALUE"""),"Acc") -> Acc | D20: =IFERROR(__xludf.DUMMYFUNCTION("""COMPUTED_VALUE"""),"Y400") -> Y400 | E20: TER001 | F20: TUTOR ANTONIO DE JANAIRO TOMASOEY | G20: TERMINAL HP | H20: KUPANG
A21: =IFERROR(__xludf.DUMMYFUNCTION("""COMPUTED_VALUE"""),45898.57057521991) -> 45898.571 | B21: =IFERROR(__xludf.DUMMYFUNCTION("""COMPUTED_VALUE"""),"YOHANIS TIPNONI") -> YOHANIS TIPNONI | C21: =IFERROR(__xludf.DUMMYFUNCTION("""COMPUTED_VALUE"""),"Reject") -> Reject | E21: KIN001 | F21: TUTOR ANTONIO DE JANAIRO TOMASOEY | G21: KING CELL | H21: KUPANG
A22: =IFERROR(__xludf.DUMMYFUNCTION("""COMPUTED_VALUE"""),45898.65866562499) -> 45898.659 | B22: =IFERROR(__xludf.DUMMYFUNCTION("""COMPUTED_VALUE"""),"WARDIA") -> WARDIA | C22: =IFERROR(__xludf.DUMMYFUNCTION("""COMPUTED_VALUE"""),"Reject") -> Reject | D22: =IFERROR(__xludf.DUMMYFUNCTION("""COMPUTED_VALUE"""),"Y400") -> Y400 | E22: SPC006 | F22: TUTOR ANDRI RUDOLOF ELI MANAFE | G22: SPC OESAPA | H22: KUPANG
A23: =IFERROR(__xludf.DUMMYFUNCTION("""COMPUTED_VALUE"""),45898.6762975) -> 45898.676 | B23: =IFERROR(__xludf.DUMMYFUNCTION("""COMPUTED_VALUE"""),"YASINTHA MBU") -> YASINTHA MBU | C23: =IFERROR(__xludf.DUMMYFUNCTION("""COMPUTED_VALUE"""),"belum dapat limit") -> belum dapat limit | D23: =IFERROR(__xludf.DUMMYFUNCTION("""COMPUTED_VALUE"""),"Y400") -> Y400 | E23: TER001 | F23: TUTOR ANTONIO DE JANAIRO TOMASOEY | G23: TERMINAL HP | H23: KUPANG
A24: =IFERROR(__xludf.DUMMYFUNCTION("""COMPUTED_VALUE"""),45898.79220520833) -> 45898.792 | B24: =IFERROR(__xludf.DUMMYFUNCTION("""COMPUTED_VALUE"""),"YASINTHA MBU") -> YASINTHA MBU | C24: =IFERROR(__xludf.DUMMYFUNCTION("""COMPUTED_VALUE"""),"Acc") -> Acc | D24: =IFERROR(__xludf.DUMMYFUNCTION("""COMPUTED_VALUE"""),"V50 LITE") -> V50 LITE | E24: TER001 | F24: TUTOR ANTONIO DE JANAIRO TOMASOEY | G24: TERMINAL HP | H24: KUPANG
A25: =IFERROR(__xludf.DUMMYFUNCTION("""COMPUTED_VALUE"""),45898.83603935185) -> 45898.836 | B25: =IFERROR(__xludf.DUMMYFUNCTION("""COMPUTED_VALUE"""),"SELVINCE BAKO") -> SELVINCE BAKO | C25: =IFERROR(__xludf.DUMMYFUNCTION("""COMPUTED_VALUE"""),"Tidak dapat limit") -> Tidak dapat limit | D25: =IFERROR(__xludf.DUMMYFUNCTION("""COMPUTED_VALUE"""),"Y400") -> Y400 | E25: SPC003 | F25: TUTOR ANDRI RUDOLOF ELI MANAFE | G25: SPC KUANINO | H25: KUPANG
A26: =IFERROR(__xludf.DUMMYFUNCTION("""COMPUTED_VALUE"""),45898.86502353009) -> 45898.865 | B26: =IFERROR(__xludf.DUMMYFUNCTION("""COMPUTED_VALUE"""),"SKOLASTIKA B TAUNAES") -> SKOLASTIKA B TAUNAES | C26: =IFERROR(__xludf.DUMMYFUNCTION("""COMPUTED_VALUE"""),"Reject") -> Reject | D26: =IFERROR(__xludf.DUMMYFUNCTION("""COMPUTED_VALUE"""),"Y400") -> Y400 | E26: SPC003 | F26: TUTOR ANDRI RUDOLOF ELI MANAFE | G26: SPC KUANINO | H26: KUPANG
A27: =IFERROR(__xludf.DUMMYFUNCTION("""COMPUTED_VALUE"""),45898.86524013889) -> 45898.865 | B27: =IFERROR(__xludf.DUMMYFUNCTION("""COMPUTED_VALUE"""),"SELVINCE BAKO") -> SELVINCE BAKO | C27: =IFERROR(__xludf.DUMMYFUNCTION("""COMPUTED_VALUE"""),"Tidak dapt limit") -> Tidak dapt limit | D27: =IFERROR(__xludf.DUMMYFUNCTION("""COMPUTED_VALUE"""),"Lain nya...") -> Lain nya... | E27: SPC003 | F27: TUTOR ANDRI RUDOLOF ELI MANAFE | G27: SPC KUANINO | H27: KUPANG
A28: =IFERROR(__xludf.DUMMYFUNCTION("""COMPUTED_VALUE"""),45898.866954363424) -> 45898.867 | B28: =IFERROR(__xludf.DUMMYFUNCTION("""COMPUTED_VALUE"""),"YOHANIS TIPNONI") -> YOHANIS TIPNONI | C28: =IFERROR(__xludf.DUMMYFUNCTION("""COMPUTED_VALUE"""),"Tidak dapat limit") -> Tidak dapat limit | D28: =IFERROR(__xludf.DUMMYFUNCTION("""COMPUTED_VALUE"""),"Y400") -> Y400 | E28: KIN001 | F28: TUTOR ANTONIO DE JANAIRO TOMASOEY | G28: KING CELL | H28: KUPANG
A29: =IFERROR(__xludf.DUMMYFUNCTION("""COMPUTED_VALUE"""),45898.867018321755) -> 45898.867 | B29: =IFERROR(__xludf.DUMMYFUNCTION("""COMPUTED_VALUE"""),"SKOLASTIKA B TAUNAES") -> SKOLASTIKA B TAUNAES | C29: =IFERROR(__xludf.DUMMYFUNCTION("""COMPUTED_VALUE"""),"Reject") -> Reject | D29: =IFERROR(__xludf.DUMMYFUNCTION("""COMPUTED_VALUE"""),"Y400") -> Y400 | E29: SPC003 | F29: TUTOR ANDRI RUDOLOF ELI MANAFE | G29: SPC KUANINO | H29: KUPANG
A30: =IFERROR(__xludf.DUMMYFUNCTION("""COMPUTED_VALUE"""),45898.869698692135) -> 45898.87 | B30: =IFERROR(__xludf.DUMMYFUNCTION("""COMPUTED_VALUE"""),"YOHANIS TIPNONI") -> YOHANIS TIPNONI | C30: =IFERROR(__xludf.DUMMYFUNCTION("""COMPUTED_VALUE"""),"Tidak ada limit") -> Tidak ada limit | D30: =IFERROR(__xludf.DUMMYFUNCTION("""COMPUTED_VALUE"""),"Y400") -> Y400 | E30: KIN001 | F30: TUTOR ANTONIO DE JANAIRO TOMASOEY | G30: KING CELL | H30: KUPANG
A31: =IFERROR(__xludf.DUMMYFUNCTION("""COMPUTED_VALUE"""),45898.870139907405) -> 45898.87 | B31: =IFERROR(__xludf.DUMMYFUNCTION("""COMPUTED_VALUE"""),"FEBRIANTHY ELISABET NA'U") -> FEBRIANTHY ELISABET NA'U | C31: =IFERROR(__xludf.DUMMYFUNCTION("""COMPUTED_VALUE"""),"Reject") -> Reject | D31: =IFERROR(__xludf.DUMMYFUNCTION("""COMPUTED_VALUE"""),"Y400") -> Y400 | E31: SPC011 | F31: TUTOR ANDRI RUDOLOF ELI MANAFE | G31: SPC STARLIGHT | H31: KUPANG
A32: =IFERROR(__xludf.DUMMYFUNCTION("""COMPUTED_VALUE"""),45898.87224603009) -> 45898.872 | B32: =IFERROR(__xludf.DUMMYFUNCTION("""COMPUTED_VALUE"""),"FEBRIANTHY ELISABET NA'U") -> FEBRIANTHY ELISABET NA'U | C32: =IFERROR(__xludf.DUMMYFUNCTION("""COMPUTED_VALUE"""),"Reject") -> Reject | D32: =IFERROR(__xludf.DUMMYFUNCTION("""COMPUTED_VALUE"""),"Y400") -> Y400 | E32: SPC011 | F32: TUTOR ANDRI RUDOLOF ELI MANAFE | G32: SPC STARLIGHT | H32: KUPANG
A33: =IFERROR(__xludf.DUMMYFUNCTION("""COMPUTED_VALUE"""),45899.52757194444) -> 45899.528 | B33: =IFERROR(__xludf.DUMMYFUNCTION("""COMPUTED_VALUE"""),"KESIA NATALIA I. BENU") -> KESIA NATALIA I. BENU | C33: =IFERROR(__xludf.DUMMYFUNCTION("""COMPUTED_VALUE"""),"ACC") -> ACC | D33: =IFERROR(__xludf.DUMMYFUNCTION("""COMPUTED_VALUE"""),"Y400 series") -> Y400 series | E33: KHA002 | F33: SPV ANFAL JUPRIADI AMBU WARU | G33: KHAIRIL CELL | H33: SUMBA
A34: =IFERROR(__xludf.DUMMYFUNCTION("""COMPUTED_VALUE"""),45899.52757194444) -> 45899.528 | B34: =IFERROR(__xludf.DUMMYFUNCTION("""COMPUTED_VALUE"""),"MARNITHA JUWIKE TIMORATI RUNESI") -> MARNITHA JUWIKE TIMORATI RUNESI | C34: =IFERROR(__xludf.DUMMYFUNCTION("""COMPUTED_VALUE"""),"ACC") -> ACC | D34: =IFERROR(__xludf.DUMMYFUNCTION("""COMPUTED_VALUE"""),"Y400 series") -> Y400 series | E34: SPC005 | F34: TUTOR ANDRI RUDOLOF ELI MANAFE | G34: SPC OESAO | H34: KUPANG
A35: =IFERROR(__xludf.DUMMYFUNCTION("""COMPUTED_VALUE"""),45899.57235034722) -> 45899.572 | B35: =IFERROR(__xludf.DUMMYFUNCTION("""COMPUTED_VALUE"""),"YOHANA NOVIANA MARIANA GAA") -> YOHANA NOVIANA MARIANA GAA | C35: =IFERROR(__xludf.DUMMYFUNCTION("""COMPUTED_VALUE"""),"No Limit") -> No Limit | E35: SPC007 | F35: TUTOR ANDRI RUDOLOF ELI MANAFE | G35: SPC PLATINUM | H35: KUPANG
A36: =IFERROR(__xludf.DUMMYFUNCTION("""COMPUTED_VALUE"""),45899.619064976854) -> 45899.619 | B36: =IFERROR(__xludf.DUMMYFUNCTION("""COMPUTED_VALUE"""),"MERDA PUTRI BUNGSU KENAT") -> MERDA PUTRI BUNGSU KENAT | C36: =IFERROR(__xludf.DUMMYFUNCTION("""COMPUTED_VALUE"""),"ACC") -> ACC | D36: =IFERROR(__xludf.DUMMYFUNCTION("""COMPUTED_VALUE"""),"Y400 series") -> Y400 series | E36: QIN001 | F36: TUTOR HERY YULIUS DILLAK | G36: QINARA CELL | H36: KABUPATEN
A37: =IFERROR(__xludf.DUMMYFUNCTION("""COMPUTED_VALUE"""),45899.774507256945) -> 45899.775 | B37: =IFERROR(__xludf.DUMMYFUNCTION("""COMPUTED_VALUE"""),"EMPI FRANGKI LIEM") -> EMPI FRANGKI LIEM | C37: =IFERROR(__xludf.DUMMYFUNCTION("""COMPUTED_VALUE"""),"ACC") -> ACC | D37: =IFERROR(__xludf.DUMMYFUNCTION("""COMPUTED_VALUE"""),"Y400 series") -> Y400 series | E37: MCE001 | F37: TUTOR ANTONIO DE JANAIRO TOMASOEY | G37: MCELL | H37: KUPANG
A38: =IFERROR(__xludf.DUMMYFUNCTION("""COMPUTED_VALUE"""),45899.774507256945) -> 45899.775 | B38: =IFERROR(__xludf.DUMMYFUNCTION("""COMPUTED_VALUE"""),"EMPI FRANGKI LIEM") -> EMPI FRANGKI LIEM | C38: =IFERROR(__xludf.DUMMYFUNCTION("""COMPUTED_VALUE"""),"ACC") -> ACC | D38: =IFERROR(__xludf.DUMMYFUNCTION("""COMPUTED_VALUE"""),"Y400 series") -> Y400 series | E38: MCE001 | F38: TUTOR ANTONIO DE JANAIRO TOMASOEY | G38: MCELL | H38: KUPANG
A39: =IFERROR(__xludf.DUMMYFUNCTION("""COMPUTED_VALUE"""),45899.78745510416) -> 45899.787 | B39: =IFERROR(__xludf.DUMMYFUNCTION("""COMPUTED_VALUE"""),"YOHANIS TIPNONI") -> YOHANIS TIPNONI | C39: =IFERROR(__xludf.DUMMYFUNCTION("""COMPUTED_VALUE"""),"No Limit") -> No Limit | E39: KIN001 | F39: TUTOR ANTONIO DE JANAIRO TOMASOEY | G39: KING CELL | H39: KUPANG
A40: =IFERROR(__xludf.DUMMYFUNCTION("""COMPUTED_VALUE"""),45899.78745510416) -> 45899.787 | B40: =IFERROR(__xludf.DUMMYFUNCTION("""COMPUTED_VALUE"""),"YOHANIS TIPNONI") -> YOHANIS TIPNONI | C40: =IFERROR(__xludf.DUMMYFUNCTION("""COMPUTED_VALUE"""),"No Limit") -> No Limit | E40: KIN001 | F40: TUTOR ANTONIO DE JANAIRO TOMASOEY | G40: KING CELL | H40: KUPANG
...

Sheet Database Promotor
A1: ID Promotor | B1: Promotor | C1: Sator | D1: Target Pengajuan | E1: ID Toko Penempatan
A2: DEW001 | B2: DEWI RAHMAN | C2: TUTOR YACOB CHRISTIAN BOLING | D2: 48 | E2: TIM001
A3: ISW001 | B3: ISWAN ASAMAU | C3: TUTOR YACOB CHRISTIAN BOLING | D3: 48 | E3: NAB001
A4: KAM001 | B4: KAMARIA ANDI BASO | C4: TUTOR YACOB CHRISTIAN BOLING | D4: 48 | E4: FAT001
A5: MEL001 | B5: MELIYANI RATNASARI SYUKRI | C5: TUTOR YACOB CHRISTIAN BOLING | D5: 48 | E5: PRI001 | G5: area kabupaten
A6: ABB001 | B6: ANGELA BOUKA BERI | C6: TUTOR YACOB CHRISTIAN BOLING | D6: 48 | E6: PRI001
A7: ARF001 | B7: ANNA RAHMATIA JUFRI | C7: TUTOR YACOB CHRISTIAN BOLING | D7: 48 | E7: BGD001
A8: PRE001 | B8: PRETI SISILIA SILA | C8: TUTOR MARSELUS M LAMBO | D8: 48 | E8: SPC009 | G8: TUTOR YACOB CHRISTIAN BOLING
A9: YUT001 | B9: YUNITA TAMELAB | C9: TUTOR MARSELUS M LAMBO | D9: 48 | E9: SRI001
A10: ADR004 | B10: ADRIANA | C10: TUTOR LEU ADOLF QICHEN LEI BAIT | D10: 48 | E10: MUT001 | G10: TUTOR LEU ADOLF QICHEN LEI BAIT
A11: BER001 | B11: BERGITHA NIA OLIN | C11: TUTOR LEU ADOLF QICHEN LEI BAIT | D11: 48 | E11: INF001 | G11: TUTOR HERY YULIUS DILLAK
A12: MAR002 | B12: MARIA DENTIANA L HAUMETAN | C12: TUTOR LEU ADOLF QICHEN LEI BAIT | D12: 48 | E12: KER001 | G12: SPV WILIBRODUS R MANEK SAMARA
A13: ATM001 | B13: ARMINDA TEKU MANEK | C13: TUTOR LEU ADOLF QICHEN LEI BAIT | D13: 48 | E13: SPC014
A14: NUR001 | B14: NUR FATIMAH MOLBANG | C14: TUTOR LEU ADOLF QICHEN LEI BAIT | D14: 48 | E14: PUT001
A15: MIN001 | B15: MARIA ISABELA NONIS | C15: TUTOR LEU ADOLF QICHEN LEI BAIT | D15: 48 | E15: MAR001
A16: ALI001 | B16: ALITA D PAU | C16: TUTOR KUSMYATI KILIMANDU | D16: 48 | E16: GLO001 | G16: area kota kupang
A17: AMB001 | B17: AMBU BAIQ JUMENAH | C17: TUTOR KUSMYATI KILIMANDU | D17: 48 | E17: SAC001 | G17: TUTOR ANTONIO DE JANAIRO TOMASOEY
A18: ANI001 | B18: ANITA ANA AMAH | C18: TUTOR KUSMYATI KILIMANDU | D18: 48 | E18: QUE001 | G18: TUTOR ANDRI RUDOLOF ELI MANAFE
A19: NOV001 | B19: NOVLIANA BARBALINA MISA | C19: TUTOR KUSMYATI KILIMANDU | D19: 48 | E19: GLO003
A20: YER001 | B20: YEREMIAS MBAWA KANJAPI | C20: TUTOR KUSMYATI KILIMANDU | D20: 48 | E20: GLO001 | G20: area sumba
A21: YOV001 | B21: YOVANDA KATRINA NAE | C21: TUTOR KUSMYATI KILIMANDU | D21: 48 | E21: QUE001 | G21: SPV ANFAL JUPRIADI AMBU WARU
A22: ASR001 | B22: ASRI NINGSI RAMBU ATA ENDI | C22: TUTOR KUSMYATI KILIMANDU | D22: 48 | E22: SPC010
A23: EST001 | B23: ESTER LUDJI | C23: TUTOR KUSMYATI KILIMANDU | D23: 48 | E23: SPC010
A24: AGW001 | B24: ANAK AGUNG SRI WULANTIWI | C24: TUTOR KUSMYATI KILIMANDU | D24: 48 | E24: DCE001
A25: HER001 | B25: HERONIMUS NAMU WALI | C25: TUTOR KUSMYATI KILIMANDU | D25: 48 | E25: SRT001
A26: ALD001 | B26: ALDIANA WELIA PANIE | C26: TUTOR HERY YULIUS DILLAK | D26: 48 | E26: QIN001
A27: ELI001 | B27: LINDA MELSIANA ELLO | C27: TUTOR HERY YULIUS DILLAK | D27: 48 | E27: AND001
A28: MAR001 | B28: MARATHA MARLINDA FANGGIDAE | C28: TUTOR HERY YULIUS DILLAK | D28: 48 | E28: AND001
A29: EME001 | B29: MERDA PUTRI BUNGSU KENAT | C29: TUTOR HERY YULIUS DILLAK | D29: 48 | E29: QIN001
A30: YRM001 | B30: ANYARMITHA SOPHIA SUEK | C30: TUTOR ANTONIO DE JANAIRO TOMASOEY | D30: 48 | E30: CEL001
A31: DWI001 | B31: DWITNEY PRETY WANGGANDIMA | C31: TUTOR ANTONIO DE JANAIRO TOMASOEY | D31: 48 | E31: CEL001
A32: EFL001 | B32: EMPI FRANGKI LIEM | C32: TUTOR ANTONIO DE JANAIRO TOMASOEY | D32: 48 | E32: MCE001
A33: FER001 | B33: FERI ELI KURNIAWAN | C33: TUTOR ANTONIO DE JANAIRO TOMASOEY | D33: 48 | E33: PLA001
... A73: AST001 | B73: ASTUTI BELA WAWO | C73: SPV ANFAL JUPRIADI AMBU WARU | D73: 48 | E73: GLO002

Sheet Database Toko
A1: ID Toko | B1: Nama Toko | C1: Area | D1: Area Detail
A2: ALI001 | B2: ALIONG CELL | C2: PULAU SUMBA | D2: SUMBA
A3: AND001 | B3: ANDYS CELL | C3: PULAU TIMOR | D3: KABUPATEN
A4: AZI001 | B4: AZIZAH CELL | C4: PULAU SUMBA | D4: SUMBA
A5: CEL001 | B5: CELLULER WORLD | C5: PULAU TIMOR | D5: KUPANG
A6: FAT001 | B6: FATIMA CELL | C6: PULAU TIMOR | D6: KABUPATEN
A7: GAR001 | B7: GARUDA CELL | C7: PULAU TIMOR | D7: KABUPATEN
A8: GIS001 | B8: GISMCELL | C8: PULAU SUMBA | D8: SUMBA
A9: GLO001 | B9: GLOBAL TEKNIK 1 | C9: PULAU SUMBA | D9: SUMBA
A10: GLO002 | B10: GLOBAL TEKNIK 2 | C10: PULAU SUMBA | D10: SUMBA
A11: GLO003 | B11: GLOBAL TEKNIK 3 | C11: PULAU SUMBA | D11: SUMBA
A12: GLO004 | B12: GLOBAL TEKNIK 4 | C12: PULAU SUMBA | D12: SUMBA
... A57: DCE001 | B57: DCELL | C57: PULAU SUMBA | D57: SUMBA

Sheet Data Penjualan Bersih
A1: Timestamp | B1: Nama Promotor | C1: Status | D1: Tipe hp | E1: ID Toko | F1: Sator | G1: Area
A2: =IFERROR(__xludf.DUMMYFUNCTION("LET( data_range, 'Master Data All'!A2:X1499, first_day, EOMONTH(TODAY(),-1)+1, stack, { IFERROR(QUERY(data_range, ""SELECT A, P, I, M WHERE P IS NOT NULL AND A IS NOT NULL"")); IFERROR(QUERY(data_range, ""SELECT A, Q, I, M WHERE Q IS NOT NU"&"LL AND A IS NOT NULL"")); IFERROR(QUERY(data_range, ""SELECT A, R, I, M WHERE R IS NOT NULL AND A IS NOT NULL"")); IFERROR(QUERY(data_range, ""SELECT A, S, I, M WHERE S IS NOT NULL AND A IS NOT NULL"")); IFERROR(QUERY(data_range, ""SELECT A, T"&", I, M WHERE T IS NOT NULL AND A IS NOT NULL"")); IFERROR(QUERY(data_range, ""SELECT A, U, I, M WHERE U IS NOT NULL AND A IS NOT NULL"")); IFERROR(QUERY(data_range, ""SELECT A, V, I, M WHERE V IS NOT NULL AND A IS NOT NULL"")); IFERROR(QUERY(d"&"ata_range, ""SELECT A, W, I, M WHERE W IS NOT NULL AND A IS NOT NULL"")); IFERROR(QUERY(data_range, ""SELECT A, X, I, M WHERE X IS NOT NULL AND A IS NOT NULL"")) }, SORT( FILTER( stack, INDEX(stack, 0, 1) >= first_day ), 1, "&"TRUE) )"),45992.000220925926) -> 45992 | B2: =IFERROR(__xludf.DUMMYFUNCTION("""COMPUTED_VALUE"""),"ROS YANE KANA LUDJI") -> ROS YANE KANA LUDJI | C2: =IFERROR(__xludf.DUMMYFUNCTION("""COMPUTED_VALUE"""),"Belum disetujui") -> Belum disetujui | E2: {=IF(B2:B1499="", "", IFNA( VLOOKUP( UPPER(TRIM(B2:B1499)), {UPPER(TRIM('Database Promotor'!B2:B1499)), 'Database Promotor'!E2:E1499}, 2, FALSE ), "Promotor Tidak Ditemukan" ) )} -> SPC013 | F2: {=IF(B2:B1499="",, IFERROR(VLOOKUP(B2:B1499, {'Database Promotor'!B:B , 'Database Promotor'!C:C}, 2, FALSE), "Sator Tdk Ditemukan"))} -> TUTOR ANDRI RUDOLOF ELI MANAFE | G2: {=IF(E2:E1499="", "", IFNA( VLOOKUP(UPPER(TRIM(E2:E1499)), {UPPER(TRIM('Database Toko'!A2:A499)), 'Database Toko'!D2:D499}, 2, FALSE ), "Detail Tdk Ditemukan" ) )} -> KUPANG
A3: =IFERROR(__xludf.DUMMYFUNCTION("""COMPUTED_VALUE"""),45992.39247590278) -> 45992.392 | B3: =IFERROR(__xludf.DUMMYFUNCTION("""COMPUTED_VALUE"""),"MARNITHA JUWIKE TIMORATI RUNESI") -> MARNITHA JUWIKE TIMORATI RUNESI | C3: =IFERROR(__xludf.DUMMYFUNCTION("""COMPUTED_VALUE"""),"Belum disetujui") -> Belum disetujui | E3: SPC005 | F3: TUTOR ANDRI RUDOLOF ELI MANAFE | G3: KUPANG
A4: =IFERROR(__xludf.DUMMYFUNCTION("""COMPUTED_VALUE"""),45992.41216761574) -> 45992.412 | B4: =IFERROR(__xludf.DUMMYFUNCTION("""COMPUTED_VALUE"""),"ROS YANE KANA LUDJI") -> ROS YANE KANA LUDJI | C4: =IFERROR(__xludf.DUMMYFUNCTION("""COMPUTED_VALUE"""),"Belum disetujui") -> Belum disetujui | E4: SPC013 | F4: TUTOR ANDRI RUDOLOF ELI MANAFE | G4: KUPANG
A5: =IFERROR(__xludf.DUMMYFUNCTION("""COMPUTED_VALUE"""),45992.42242364584) -> 45992.422 | B5: =IFERROR(__xludf.DUMMYFUNCTION("""COMPUTED_VALUE"""),"ANDHIKA ULLY") -> ANDHIKA ULLY | C5: =IFERROR(__xludf.DUMMYFUNCTION("""COMPUTED_VALUE"""),"Belum disetujui") -> Belum disetujui | E5: ERA001 | F5: TUTOR ANTONIO DE JANAIRO TOMASOEY | G5: KUPANG
A6: =IFERROR(__xludf.DUMMYFUNCTION("""COMPUTED_VALUE"""),45992.42366331018) -> 45992.424 | B6: =IFERROR(__xludf.DUMMYFUNCTION("""COMPUTED_VALUE"""),"MARNITHA JUWIKE TIMORATI RUNESI") -> MARNITHA JUWIKE TIMORATI RUNESI | C6: =IFERROR(__xludf.DUMMYFUNCTION("""COMPUTED_VALUE"""),"Belum disetujui") -> Belum disetujui | E6: SPC005 | F6: TUTOR ANDRI RUDOLOF ELI MANAFE | G6: KUPANG
A7: =IFERROR(__xludf.DUMMYFUNCTION("""COMPUTED_VALUE"""),45992.43756385417) -> 45992.438 | B7: =IFERROR(__xludf.DUMMYFUNCTION("""COMPUTED_VALUE"""),"AINI RAHMATINI NATALIA MOESTAKIM") -> AINI RAHMATINI NATALIA MOESTAKIM | C7: =IFERROR(__xludf.DUMMYFUNCTION("""COMPUTED_VALUE"""),"Dapat limit tapi belum diproses") -> Dapat limit tapi belum diproses | D7: =IFERROR(__xludf.DUMMYFUNCTION("""COMPUTED_VALUE"""),"Y21d series") -> Y21d series | E7: SPC006 | F7: TUTOR ANDRI RUDOLOF ELI MANAFE | G7: KUPANG
A8: =IFERROR(__xludf.DUMMYFUNCTION("""COMPUTED_VALUE"""),45992.46769275463) -> 45992.468 | B8: =IFERROR(__xludf.DUMMYFUNCTION("""COMPUTED_VALUE"""),"EMPI FRANGKI LIEM") -> EMPI FRANGKI LIEM | C8: =IFERROR(__xludf.DUMMYFUNCTION("""COMPUTED_VALUE"""),"Belum disetujui") -> Belum disetujui | E8: MCE001 | F8: TUTOR ANTONIO DE JANAIRO TOMASOEY | G8: KUPANG
A9: =IFERROR(__xludf.DUMMYFUNCTION("""COMPUTED_VALUE"""),45992.50544042824) -> 45992.505 | B9: =IFERROR(__xludf.DUMMYFUNCTION("""COMPUTED_VALUE"""),"YENDRI ELISHABET BERELOE") -> YENDRI ELISHABET BERELOE | C9: =IFERROR(__xludf.DUMMYFUNCTION("""COMPUTED_VALUE"""),"Belum disetujui") -> Belum disetujui | E9: SCO001 | F9: TUTOR ANTONIO DE JANAIRO TOMASOEY | G9: KUPANG
A10: =IFERROR(__xludf.DUMMYFUNCTION("""COMPUTED_VALUE"""),45992.564250324074) -> 45992.564 | B10: =IFERROR(__xludf.DUMMYFUNCTION("""COMPUTED_VALUE"""),"ANNA RAHMATIA JUFRI") -> ANNA RAHMATIA JUFRI | C10: =IFERROR(__xludf.DUMMYFUNCTION("""COMPUTED_VALUE"""),"Belum disetujui") -> Belum disetujui | E10: BGD001 | F10: TUTOR YACOB CHRISTIAN BOLING | G10: KABUPATEN
A11: =IFERROR(__xludf.DUMMYFUNCTION("""COMPUTED_VALUE"""),45992.568997662034) -> 45992.569 | B11: =IFERROR(__xludf.DUMMYFUNCTION("""COMPUTED_VALUE"""),"SANTI MARIA LUKMINI NAHAK") -> SANTI MARIA LUKMINI NAHAK | C11: =IFERROR(__xludf.DUMMYFUNCTION("""COMPUTED_VALUE"""),"Belum disetujui") -> Belum disetujui | E11: PKR001 | F11: SPV WILIBRODUS R MANEK SAMARA | G11: KABUPATEN
A12: =IFERROR(__xludf.DUMMYFUNCTION("""COMPUTED_VALUE"""),45992.56975221065) -> 45992.57 | B12: =IFERROR(__xludf.DUMMYFUNCTION("""COMPUTED_VALUE"""),"RESTIANY MARIA LUAN KALI") -> RESTIANY MARIA LUAN KALI | C12: =IFERROR(__xludf.DUMMYFUNCTION("""COMPUTED_VALUE"""),"Belum disetujui") -> Belum disetujui | E12: SPC007 | F12: TUTOR ANDRI RUDOLOF ELI MANAFE | G12: KUPANG
A13: =IFERROR(__xludf.DUMMYFUNCTION("""COMPUTED_VALUE"""),45992.575315960654) -> 45992.575 | B13: =IFERROR(__xludf.DUMMYFUNCTION("""COMPUTED_VALUE"""),"NUR FATIMAH MOLBANG") -> NUR FATIMAH MOLBANG | C13: =IFERROR(__xludf.DUMMYFUNCTION("""COMPUTED_VALUE"""),"Belum disetujui") -> Belum disetujui | E13: PUT001 | F13: TUTOR LEU ADOLF QICHEN LEI BAIT | G13: KABUPATEN
A14: =IFERROR(__xludf.DUMMYFUNCTION("""COMPUTED_VALUE"""),45992.5792065162) -> 45992.579 | B14: =IFERROR(__xludf.DUMMYFUNCTION("""COMPUTED_VALUE"""),"NUR FATIMAH MOLBANG") -> NUR FATIMAH MOLBANG | C14: =IFERROR(__xludf.DUMMYFUNCTION("""COMPUTED_VALUE"""),"Belum disetujui") -> Belum disetujui | E14: PUT001 | F14: TUTOR LEU ADOLF QICHEN LEI BAIT | G14: KABUPATEN
A15: =IFERROR(__xludf.DUMMYFUNCTION("""COMPUTED_VALUE"""),45992.583182372684) -> 45992.583 | B15: =IFERROR(__xludf.DUMMYFUNCTION("""COMPUTED_VALUE"""),"PATRIANI MENGI ULY") -> PATRIANI MENGI ULY | C15: =IFERROR(__xludf.DUMMYFUNCTION("""COMPUTED_VALUE"""),"Belum disetujui") -> Belum disetujui | E15: SPC004 | F15: TUTOR ANDRI RUDOLOF ELI MANAFE | G15: KUPANG
A16: =IFERROR(__xludf.DUMMYFUNCTION("""COMPUTED_VALUE"""),45992.60638649306) -> 45992.606 | B16: =IFERROR(__xludf.DUMMYFUNCTION("""COMPUTED_VALUE"""),"BERGITHA NIA OLIN") -> BERGITHA NIA OLIN | C16: =IFERROR(__xludf.DUMMYFUNCTION("""COMPUTED_VALUE"""),"Belum disetujui") -> Belum disetujui | E16: INF001 | F16: TUTOR LEU ADOLF QICHEN LEI BAIT | G16: KABUPATEN
A17: =IFERROR(__xludf.DUMMYFUNCTION("""COMPUTED_VALUE"""),45992.61478524306) -> 45992.615 | B17: =IFERROR(__xludf.DUMMYFUNCTION("""COMPUTED_VALUE"""),"YENDRI ELISHABET BERELOE") -> YENDRI ELISHABET BERELOE | C17: =IFERROR(__xludf.DUMMYFUNCTION("""COMPUTED_VALUE"""),"Dapat limit tapi belum diproses") -> Dapat limit tapi belum diproses | D17: =IFERROR(__xludf.DUMMYFUNCTION("""COMPUTED_VALUE"""),"Y21d series") -> Y21d series | E17: SCO001 | F17: TUTOR ANTONIO DE JANAIRO TOMASOEY | G17: KUPANG
A18: =IFERROR(__xludf.DUMMYFUNCTION("""COMPUTED_VALUE"""),45992.67328905092) -> 45992.673 | B18: =IFERROR(__xludf.DUMMYFUNCTION("""COMPUTED_VALUE"""),"NABILA RAHMAWATI") -> NABILA RAHMAWATI | C18: =IFERROR(__xludf.DUMMYFUNCTION("""COMPUTED_VALUE"""),"Belum disetujui") -> Belum disetujui | E18: AZI001 | F18: SPV ANFAL JUPRIADI AMBU WARU | G18: SUMBA
A19: =IFERROR(__xludf.DUMMYFUNCTION("""COMPUTED_VALUE"""),45992.728126319445) -> 45992.728 | B19: =IFERROR(__xludf.DUMMYFUNCTION("""COMPUTED_VALUE"""),"WARDIA") -> WARDIA | C19: =IFERROR(__xludf.DUMMYFUNCTION("""COMPUTED_VALUE"""),"Belum disetujui") -> Belum disetujui | E19: SPC006 | F19: TUTOR ANDRI RUDOLOF ELI MANAFE | G19: KUPANG
A20: =IFERROR(__xludf.DUMMYFUNCTION("""COMPUTED_VALUE"""),45992.74368403935) -> 45992.744 | B20: =IFERROR(__xludf.DUMMYFUNCTION("""COMPUTED_VALUE"""),"ESTER LUDJI") -> ESTER LUDJI | C20: =IFERROR(__xludf.DUMMYFUNCTION("""COMPUTED_VALUE"""),"ACC") -> ACC | D20: =IFERROR(__xludf.DUMMYFUNCTION("""COMPUTED_VALUE"""),"Y21d series") -> Y21d series | E20: SPC010 | F20: TUTOR KUSMYATI KILIMANDU | G20: SUMBA
A21: =IFERROR(__xludf.DUMMYFUNCTION("""COMPUTED_VALUE"""),45992.767859479165) -> 45992.768 | B21: =IFERROR(__xludf.DUMMYFUNCTION("""COMPUTED_VALUE"""),"ESTER LUDJI") -> ESTER LUDJI | C21: =IFERROR(__xludf.DUMMYFUNCTION("""COMPUTED_VALUE"""),"Belum disetujui") -> Belum disetujui | E21: SPC010 | F21: TUTOR KUSMYATI KILIMANDU | G21: SUMBA
A22: =IFERROR(__xludf.DUMMYFUNCTION("""COMPUTED_VALUE"""),45992.77763405093) -> 45992.778 | B22: =IFERROR(__xludf.DUMMYFUNCTION("""COMPUTED_VALUE"""),"ASRI NINGSI RAMBU ATA ENDI") -> ASRI NINGSI RAMBU ATA ENDI | C22: =IFERROR(__xludf.DUMMYFUNCTION("""COMPUTED_VALUE"""),"Dapat limit tapi belum diproses") -> Dapat limit tapi belum diproses | D22: =IFERROR(__xludf.DUMMYFUNCTION("""COMPUTED_VALUE"""),"Y400 series") -> Y400 series | E22: SPC010 | F22: TUTOR KUSMYATI KILIMANDU | G22: SUMBA
A23: =IFERROR(__xludf.DUMMYFUNCTION("""COMPUTED_VALUE"""),45992.77939128473) -> 45992.779 | B23: =IFERROR(__xludf.DUMMYFUNCTION("""COMPUTED_VALUE"""),"ROS YANE KANA LUDJI") -> ROS YANE KANA LUDJI | C23: =IFERROR(__xludf.DUMMYFUNCTION("""COMPUTED_VALUE"""),"Belum disetujui") -> Belum disetujui | E23: SPC013 | F23: TUTOR ANDRI RUDOLOF ELI MANAFE | G23: KUPANG
A24: =IFERROR(__xludf.DUMMYFUNCTION("""COMPUTED_VALUE"""),45992.78130732638) -> 45992.781 | B24: =IFERROR(__xludf.DUMMYFUNCTION("""COMPUTED_VALUE"""),"BERGITHA NIA OLIN") -> BERGITHA NIA OLIN | C24: =IFERROR(__xludf.DUMMYFUNCTION("""COMPUTED_VALUE"""),"ACC") -> ACC | D24: =IFERROR(__xludf.DUMMYFUNCTION("""COMPUTED_VALUE"""),"V60 Lite series") -> V60 Lite series | E24: INF001 | F24: TUTOR LEU ADOLF QICHEN LEI BAIT | G24: KABUPATEN
A25: =IFERROR(__xludf.DUMMYFUNCTION("""COMPUTED_VALUE"""),45992.796267280086) -> 45992.796 | B25: =IFERROR(__xludf.DUMMYFUNCTION("""COMPUTED_VALUE"""),"SANTI MARIA LUKMINI NAHAK") -> SANTI MARIA LUKMINI NAHAK | C25: =IFERROR(__xludf.DUMMYFUNCTION("""COMPUTED_VALUE"""),"Belum disetujui") -> Belum disetujui | E25: PKR001 | F25: SPV WILIBRODUS R MANEK SAMARA | G25: KABUPATEN
A26: =IFERROR(__xludf.DUMMYFUNCTION("""COMPUTED_VALUE"""),45992.819738726845) -> 45992.82 | B26: =IFERROR(__xludf.DUMMYFUNCTION("""COMPUTED_VALUE"""),"YOVANDA KATRINA NAE") -> YOVANDA KATRINA NAE | C26: =IFERROR(__xludf.DUMMYFUNCTION("""COMPUTED_VALUE"""),"Belum disetujui") -> Belum disetujui | E26: QUE001 | F26: TUTOR KUSMYATI KILIMANDU | G26: SUMBA
A27: =IFERROR(__xludf.DUMMYFUNCTION("""COMPUTED_VALUE"""),45992.83968498843) -> 45992.84 | B27: =IFERROR(__xludf.DUMMYFUNCTION("""COMPUTED_VALUE"""),"WINDRI MANOE") -> WINDRI MANOE | C27: =IFERROR(__xludf.DUMMYFUNCTION("""COMPUTED_VALUE"""),"Belum disetujui") -> Belum disetujui | E27: CEL001 | F27: TUTOR ANTONIO DE JANAIRO TOMASOEY | G27: KUPANG
A28: =IFERROR(__xludf.DUMMYFUNCTION("""COMPUTED_VALUE"""),45992.840489166665) -> 45992.84 | B28: =IFERROR(__xludf.DUMMYFUNCTION("""COMPUTED_VALUE"""),"WINDRI MANOE") -> WINDRI MANOE | C28: =IFERROR(__xludf.DUMMYFUNCTION("""COMPUTED_VALUE"""),"Belum disetujui") -> Belum disetujui | E28: CEL001 | F28: TUTOR ANTONIO DE JANAIRO TOMASOEY | G28: KUPANG
A29: =IFERROR(__xludf.DUMMYFUNCTION("""COMPUTED_VALUE"""),45992.85128471065) -> 45992.851 | B29: =IFERROR(__xludf.DUMMYFUNCTION("""COMPUTED_VALUE"""),"DWITNEY PRETY WANGGANDIMA") -> DWITNEY PRETY WANGGANDIMA | C29: =IFERROR(__xludf.DUMMYFUNCTION("""COMPUTED_VALUE"""),"Belum disetujui") -> Belum disetujui | E29: CEL001 | F29: TUTOR ANTONIO DE JANAIRO TOMASOEY | G29: KUPANG
A30: =IFERROR(__xludf.DUMMYFUNCTION("""COMPUTED_VALUE"""),45992.85280275463) -> 45992.853 | B30: =IFERROR(__xludf.DUMMYFUNCTION("""COMPUTED_VALUE"""),"DWITNEY PRETY WANGGANDIMA") -> DWITNEY PRETY WANGGANDIMA | C30: =IFERROR(__xludf.DUMMYFUNCTION("""COMPUTED_VALUE"""),"Belum disetujui") -> Belum disetujui | E30: CEL001 | F30: TUTOR ANTONIO DE JANAIRO TOMASOEY | G30: KUPANG
A31: =IFERROR(__xludf.DUMMYFUNCTION("""COMPUTED_VALUE"""),45992.866584537034) -> 45992.867 | B31: =IFERROR(__xludf.DUMMYFUNCTION("""COMPUTED_VALUE"""),"YOVANDA KATRINA NAE") -> YOVANDA KATRINA NAE | C31: =IFERROR(__xludf.DUMMYFUNCTION("""COMPUTED_VALUE"""),"ACC") -> ACC | D31: =IFERROR(__xludf.DUMMYFUNCTION("""COMPUTED_VALUE"""),"Y21d series") -> Y21d series | E31: QUE001 | F31: TUTOR KUSMYATI KILIMANDU | G31: SUMBA
A32: =IFERROR(__xludf.DUMMYFUNCTION("""COMPUTED_VALUE"""),45992.90303767362) -> 45992.903 | B32: =IFERROR(__xludf.DUMMYFUNCTION("""COMPUTED_VALUE"""),"HERONIMUS NAMU WALI") -> HERONIMUS NAMU WALI | C32: =IFERROR(__xludf.DUMMYFUNCTION("""COMPUTED_VALUE"""),"ACC") -> ACC | D32: =IFERROR(__xludf.DUMMYFUNCTION("""COMPUTED_VALUE"""),"Y21d series") -> Y21d series | E32: SRT001 | F32: TUTOR KUSMYATI KILIMANDU | G32: SUMBA
A33: =IFERROR(__xludf.DUMMYFUNCTION("""COMPUTED_VALUE"""),45992.90552940972) -> 45992.906 | B33: =IFERROR(__xludf.DUMMYFUNCTION("""COMPUTED_VALUE"""),"HERONIMUS NAMU WALI") -> HERONIMUS NAMU WALI | C33: =IFERROR(__xludf.DUMMYFUNCTION("""COMPUTED_VALUE"""),"Belum disetujui") -> Belum disetujui | E33: SRT001 | F33: TUTOR KUSMYATI KILIMANDU | G33: SUMBA
A34: =IFERROR(__xludf.DUMMYFUNCTION("""COMPUTED_VALUE"""),45993.40507277778) -> 45993.405 | B34: =IFERROR(__xludf.DUMMYFUNCTION("""COMPUTED_VALUE"""),"AZ ZAHRA SITI ZAINAB") -> AZ ZAHRA SITI ZAINAB | C34: =IFERROR(__xludf.DUMMYFUNCTION("""COMPUTED_VALUE"""),"Belum disetujui") -> Belum disetujui | E34: PIT001 | F34: SPV ANFAL JUPRIADI AMBU WARU | G34: SUMBA
A35: =IFERROR(__xludf.DUMMYFUNCTION("""COMPUTED_VALUE"""),45993.41075219907) -> 45993.411 | B35: =IFERROR(__xludf.DUMMYFUNCTION("""COMPUTED_VALUE"""),"YUNITA TAMELAB") -> YUNITA TAMELAB | C35: =IFERROR(__xludf.DUMMYFUNCTION("""COMPUTED_VALUE"""),"Belum disetujui") -> Belum disetujui | E35: SRI001 | F35: TUTOR MARSELUS M LAMBO | G35: KABUPATEN
A36: =IFERROR(__xludf.DUMMYFUNCTION("""COMPUTED_VALUE"""),45993.416915821756) -> 45993.417 | B36: =IFERROR(__xludf.DUMMYFUNCTION("""COMPUTED_VALUE"""),"PUSPA ANGGREINI") -> PUSPA ANGGREINI | C36: =IFERROR(__xludf.DUMMYFUNCTION("""COMPUTED_VALUE"""),"Dapat limit tapi belum diproses") -> Dapat limit tapi belum diproses | D36: =IFERROR(__xludf.DUMMYFUNCTION("""COMPUTED_VALUE"""),"Y21d series") -> Y21d series | E36: GLO002 | F36: SPV ANFAL JUPRIADI AMBU WARU | G36: SUMBA
A37: =IFERROR(__xludf.DUMMYFUNCTION("""COMPUTED_VALUE"""),45993.43785559028) -> 45993.438 | B37: =IFERROR(__xludf.DUMMYFUNCTION("""COMPUTED_VALUE"""),"ASTUTI BELA WAWO") -> ASTUTI BELA WAWO | C37: =IFERROR(__xludf.DUMMYFUNCTION("""COMPUTED_VALUE"""),"Belum disetujui") -> Belum disetujui | E37: GLO002 | F37: SPV ANFAL JUPRIADI AMBU WARU | G37: SUMBA
A38: =IFERROR(__xludf.DUMMYFUNCTION("""COMPUTED_VALUE"""),45993.43924400463) -> 45993.439 | B38: =IFERROR(__xludf.DUMMYFUNCTION("""COMPUTED_VALUE"""),"ASTUTI BELA WAWO") -> ASTUTI BELA WAWO | C38: =IFERROR(__xludf.DUMMYFUNCTION("""COMPUTED_VALUE"""),"Belum disetujui") -> Belum disetujui | E38: GLO002 | F38: SPV ANFAL JUPRIADI AMBU WARU | G38: SUMBA
A39: =IFERROR(__xludf.DUMMYFUNCTION("""COMPUTED_VALUE"""),45993.440446458335) -> 45993.44 | B39: =IFERROR(__xludf.DUMMYFUNCTION("""COMPUTED_VALUE"""),"ASTUTI BELA WAWO") -> ASTUTI BELA WAWO | C39: =IFERROR(__xludf.DUMMYFUNCTION("""COMPUTED_VALUE"""),"Belum disetujui") -> Belum disetujui | E39: GLO002 | F39: SPV ANFAL JUPRIADI AMBU WARU | G39: SUMBA
A40: =IFERROR(__xludf.DUMMYFUNCTION("""COMPUTED_VALUE"""),45993.47803436343) -> 45993.478 | B40: =IFERROR(__xludf.DUMMYFUNCTION("""COMPUTED_VALUE"""),"PRETI SISILIA SILA") -> PRETI SISILIA SILA | C40: =IFERROR(__xludf.DUMMYFUNCTION("""COMPUTED_VALUE"""),"Dapat limit tapi belum diproses") -> Dapat limit tapi belum diproses | D40: =IFERROR(__xludf.DUMMYFUNCTION("""COMPUTED_VALUE"""),"Y21d series") -> Y21d series | E40: SPC009 | F40: TUTOR MARSELUS M LAMBO | G40: KABUPATEN
...

Sheet Data Gabungan Timor Sumba
A1: Timestamp | B1: Nama Promotor | C1: Status | D1: Tipe hp
A2: =IFERROR(__xludf.DUMMYFUNCTION("LET( data_range, 'Master Data All'!A2:X1501, first_day, EOMONTH(TODAY(),-1)+1, stack, { IFERROR(QUERY(data_range, ""SELECT A, P, I, M WHERE P IS NOT NULL AND A IS NOT NULL"")); IFERROR(QUERY(data_range, ""SELECT A, Q, I, M WHERE Q IS NOT NU"&"LL AND A IS NOT NULL"")); IFERROR(QUERY(data_range, ""SELECT A, R, I, M WHERE R IS NOT NULL AND A IS NOT NULL"")); IFERROR(QUERY(data_range, ""SELECT A, S, I, M WHERE S IS NOT NULL AND A IS NOT NULL"")); IFERROR(QUERY(data_range, ""SELECT A, T"&", I, M WHERE T IS NOT NULL AND A IS NOT NULL"")); IFERROR(QUERY(data_range, ""SELECT A, U, I, M WHERE U IS NOT NULL AND A IS NOT NULL"")); IFERROR(QUERY(data_range, ""SELECT A, V, I, M WHERE V IS NOT NULL AND A IS NOT NULL"")); IFERROR(QUERY(d"&"ata_range, ""SELECT A, W, I, M WHERE W IS NOT NULL AND A IS NOT NULL"")); IFERROR(QUERY(data_range, ""SELECT A, X, I, M WHERE X IS NOT NULL AND A IS NOT NULL"")) }, SORT( FILTER( stack, INDEX(stack, 0, 1) >= first_day ), 1, "&"TRUE) )"),45992.000220925926) -> 45992 | B2: =IFERROR(__xludf.DUMMYFUNCTION("""COMPUTED_VALUE"""),"ROS YANE KANA LUDJI") -> ROS YANE KANA LUDJI | C2: =IFERROR(__xludf.DUMMYFUNCTION("""COMPUTED_VALUE"""),"Belum disetujui") -> Belum disetujui
A3: =IFERROR(__xludf.DUMMYFUNCTION("""COMPUTED_VALUE"""),45992.39247590278) -> 45992.392 | B3: =IFERROR(__xludf.DUMMYFUNCTION("""COMPUTED_VALUE"""),"MARNITHA JUWIKE TIMORATI RUNESI") -> MARNITHA JUWIKE TIMORATI RUNESI | C3: =IFERROR(__xludf.DUMMYFUNCTION("""COMPUTED_VALUE"""),"Belum disetujui") -> Belum disetujui
A4: =IFERROR(__xludf.DUMMYFUNCTION("""COMPUTED_VALUE"""),45992.41216761574) -> 45992.412 | B4: =IFERROR(__xludf.DUMMYFUNCTION("""COMPUTED_VALUE"""),"ROS YANE KANA LUDJI") -> ROS YANE KANA LUDJI | C4: =IFERROR(__xludf.DUMMYFUNCTION("""COMPUTED_VALUE"""),"Belum disetujui") -> Belum disetujui
A5: =IFERROR(__xludf.DUMMYFUNCTION("""COMPUTED_VALUE"""),45992.42242364584) -> 45992.422 | B5: =IFERROR(__xludf.DUMMYFUNCTION("""COMPUTED_VALUE"""),"ANDHIKA ULLY") -> ANDHIKA ULLY | C5: =IFERROR(__xludf.DUMMYFUNCTION("""COMPUTED_VALUE"""),"Belum disetujui") -> Belum disetujui
A6: =IFERROR(__xludf.DUMMYFUNCTION("""COMPUTED_VALUE"""),45992.42366331018) -> 45992.424 | B6: =IFERROR(__xludf.DUMMYFUNCTION("""COMPUTED_VALUE"""),"MARNITHA JUWIKE TIMORATI RUNESI") -> MARNITHA JUWIKE TIMORATI RUNESI | C6: =IFERROR(__xludf.DUMMYFUNCTION("""COMPUTED_VALUE"""),"Belum disetujui") -> Belum disetujui
A7: =IFERROR(__xludf.DUMMYFUNCTION("""COMPUTED_VALUE"""),45992.43756385417) -> 45992.438 | B7: =IFERROR(__xludf.DUMMYFUNCTION("""COMPUTED_VALUE"""),"AINI RAHMATINI NATALIA MOESTAKIM") -> AINI RAHMATINI NATALIA MOESTAKIM | C7: =IFERROR(__xludf.DUMMYFUNCTION("""COMPUTED_VALUE"""),"Dapat limit tapi belum diproses") -> Dapat limit tapi belum diproses | D7: =IFERROR(__xludf.DUMMYFUNCTION("""COMPUTED_VALUE"""),"Y21d series") -> Y21d series
A8: =IFERROR(__xludf.DUMMYFUNCTION("""COMPUTED_VALUE"""),45992.46769275463) -> 45992.468 | B8: =IFERROR(__xludf.DUMMYFUNCTION("""COMPUTED_VALUE"""),"EMPI FRANGKI LIEM") -> EMPI FRANGKI LIEM | C8: =IFERROR(__xludf.DUMMYFUNCTION("""COMPUTED_VALUE"""),"Belum disetujui") -> Belum disetujui
A9: =IFERROR(__xludf.DUMMYFUNCTION("""COMPUTED_VALUE"""),45992.50544042824) -> 45992.505 | B9: =IFERROR(__xludf.DUMMYFUNCTION("""COMPUTED_VALUE"""),"YENDRI ELISHABET BERELOE") -> YENDRI ELISHABET BERELOE | C9: =IFERROR(__xludf.DUMMYFUNCTION("""COMPUTED_VALUE"""),"Belum disetujui") -> Belum disetujui
A10: =IFERROR(__xludf.DUMMYFUNCTION("""COMPUTED_VALUE"""),45992.564250324074) -> 45992.564 | B10: =IFERROR(__xludf.DUMMYFUNCTION("""COMPUTED_VALUE"""),"ANNA RAHMATIA JUFRI") -> ANNA RAHMATIA JUFRI | C10: =IFERROR(__xludf.DUMMYFUNCTION("""COMPUTED_VALUE"""),"Belum disetujui") -> Belum disetujui
A11: =IFERROR(__xludf.DUMMYFUNCTION("""COMPUTED_VALUE"""),45992.568997662034) -> 45992.569 | B11: =IFERROR(__xludf.DUMMYFUNCTION("""COMPUTED_VALUE"""),"SANTI MARIA LUKMINI NAHAK") -> SANTI MARIA LUKMINI NAHAK | C11: =IFERROR(__xludf.DUMMYFUNCTION("""COMPUTED_VALUE"""),"Belum disetujui") -> Belum disetujui
A12: =IFERROR(__xludf.DUMMYFUNCTION("""COMPUTED_VALUE"""),45992.56975221065) -> 45992.57 | B12: =IFERROR(__xludf.DUMMYFUNCTION("""COMPUTED_VALUE"""),"RESTIANY MARIA LUAN KALI") -> RESTIANY MARIA LUAN KALI | C12: =IFERROR(__xludf.DUMMYFUNCTION("""COMPUTED_VALUE"""),"Belum disetujui") -> Belum disetujui
A13: =IFERROR(__xludf.DUMMYFUNCTION("""COMPUTED_VALUE"""),45992.575315960654) -> 45992.575 | B13: =IFERROR(__xludf.DUMMYFUNCTION("""COMPUTED_VALUE"""),"NUR FATIMAH MOLBANG") -> NUR FATIMAH MOLBANG | C13: =IFERROR(__xludf.DUMMYFUNCTION("""COMPUTED_VALUE"""),"Belum disetujui") -> Belum disetujui
A14: =IFERROR(__xludf.DUMMYFUNCTION("""COMPUTED_VALUE"""),45992.5792065162) -> 45992.579 | B14: =IFERROR(__xludf.DUMMYFUNCTION("""COMPUTED_VALUE"""),"NUR FATIMAH MOLBANG") -> NUR FATIMAH MOLBANG | C14: =IFERROR(__xludf.DUMMYFUNCTION("""COMPUTED_VALUE"""),"Belum disetujui") -> Belum disetujui
A15: =IFERROR(__xludf.DUMMYFUNCTION("""COMPUTED_VALUE"""),45992.583182372684) -> 45992.583 | B15: =IFERROR(__xludf.DUMMYFUNCTION("""COMPUTED_VALUE"""),"PATRIANI MENGI ULY") -> PATRIANI MENGI ULY | C15: =IFERROR(__xludf.DUMMYFUNCTION("""COMPUTED_VALUE"""),"Belum disetujui") -> Belum disetujui
A16: =IFERROR(__xludf.DUMMYFUNCTION("""COMPUTED_VALUE"""),45992.60638649306) -> 45992.606 | B16: =IFERROR(__xludf.DUMMYFUNCTION("""COMPUTED_VALUE"""),"BERGITHA NIA OLIN") -> BERGITHA NIA OLIN | C16: =IFERROR(__xludf.DUMMYFUNCTION("""COMPUTED_VALUE"""),"Belum disetujui") -> Belum disetujui
A17: =IFERROR(__xludf.DUMMYFUNCTION("""COMPUTED_VALUE"""),45992.61478524306) -> 45992.615 | B17: =IFERROR(__xludf.DUMMYFUNCTION("""COMPUTED_VALUE"""),"YENDRI ELISHABET BERELOE") -> YENDRI ELISHABET BERELOE | C17: =IFERROR(__xludf.DUMMYFUNCTION("""COMPUTED_VALUE"""),"Dapat limit tapi belum diproses") -> Dapat limit tapi belum diproses | D17: =IFERROR(__xludf.DUMMYFUNCTION("""COMPUTED_VALUE"""),"Y21d series") -> Y21d series
A18: =IFERROR(__xludf.DUMMYFUNCTION("""COMPUTED_VALUE"""),45992.67328905092) -> 45992.673 | B18: =IFERROR(__xludf.DUMMYFUNCTION("""COMPUTED_VALUE"""),"NABILA RAHMAWATI") -> NABILA RAHMAWATI | C18: =IFERROR(__xludf.DUMMYFUNCTION("""COMPUTED_VALUE"""),"Belum disetujui") -> Belum disetujui
A19: =IFERROR(__xludf.DUMMYFUNCTION("""COMPUTED_VALUE"""),45992.728126319445) -> 45992.728 | B19: =IFERROR(__xludf.DUMMYFUNCTION("""COMPUTED_VALUE"""),"WARDIA") -> WARDIA | C19: =IFERROR(__xludf.DUMMYFUNCTION("""COMPUTED_VALUE"""),"Belum disetujui") -> Belum disetujui
A20: =IFERROR(__xludf.DUMMYFUNCTION("""COMPUTED_VALUE"""),45992.74368403935) -> 45992.744 | B20: =IFERROR(__xludf.DUMMYFUNCTION("""COMPUTED_VALUE"""),"ESTER LUDJI") -> ESTER LUDJI | C20: =IFERROR(__xludf.DUMMYFUNCTION("""COMPUTED_VALUE"""),"ACC") -> ACC | D20: =IFERROR(__xludf.DUMMYFUNCTION("""COMPUTED_VALUE"""),"Y21d series") -> Y21d series
A21: =IFERROR(__xludf.DUMMYFUNCTION("""COMPUTED_VALUE"""),45992.767859479165) -> 45992.768 | B21: =IFERROR(__xludf.DUMMYFUNCTION("""COMPUTED_VALUE"""),"ESTER LUDJI") -> ESTER LUDJI | C21: =IFERROR(__xludf.DUMMYFUNCTION("""COMPUTED_VALUE"""),"Belum disetujui") -> Belum disetujui
A22: =IFERROR(__xludf.DUMMYFUNCTION("""COMPUTED_VALUE"""),45992.77763405093) -> 45992.778 | B22: =IFERROR(__xludf.DUMMYFUNCTION("""COMPUTED_VALUE"""),"ASRI NINGSI RAMBU ATA ENDI") -> ASRI NINGSI RAMBU ATA ENDI | C22: =IFERROR(__xludf.DUMMYFUNCTION("""COMPUTED_VALUE"""),"Dapat limit tapi belum diproses") -> Dapat limit tapi belum diproses | D22: =IFERROR(__xludf.DUMMYFUNCTION("""COMPUTED_VALUE"""),"Y400 series") -> Y400 series
A23: =IFERROR(__xludf.DUMMYFUNCTION("""COMPUTED_VALUE"""),45992.77939128473) -> 45992.779 | B23: =IFERROR(__xludf.DUMMYFUNCTION("""COMPUTED_VALUE"""),"ROS YANE KANA LUDJI") -> ROS YANE KANA LUDJI | C23: =IFERROR(__xludf.DUMMYFUNCTION("""COMPUTED_VALUE"""),"Belum disetujui") -> Belum disetujui
A24: =IFERROR(__xludf.DUMMYFUNCTION("""COMPUTED_VALUE"""),45992.78130732638) -> 45992.781 | B24: =IFERROR(__xludf.DUMMYFUNCTION("""COMPUTED_VALUE"""),"BERGITHA NIA OLIN") -> BERGITHA NIA OLIN | C24: =IFERROR(__xludf.DUMMYFUNCTION("""COMPUTED_VALUE"""),"ACC") -> ACC | D24: =IFERROR(__xludf.DUMMYFUNCTION("""COMPUTED_VALUE"""),"V60 Lite series") -> V60 Lite series
A25: =IFERROR(__xludf.DUMMYFUNCTION("""COMPUTED_VALUE"""),45992.796267280086) -> 45992.796 | B25: =IFERROR(__xludf.DUMMYFUNCTION("""COMPUTED_VALUE"""),"SANTI MARIA LUKMINI NAHAK") -> SANTI MARIA LUKMINI NAHAK | C25: =IFERROR(__xludf.DUMMYFUNCTION("""COMPUTED_VALUE"""),"Belum disetujui") -> Belum disetujui
A26: =IFERROR(__xludf.DUMMYFUNCTION("""COMPUTED_VALUE"""),45992.819738726845) -> 45992.82 | B26: =IFERROR(__xludf.DUMMYFUNCTION("""COMPUTED_VALUE"""),"YOVANDA KATRINA NAE") -> YOVANDA KATRINA NAE | C26: =IFERROR(__xludf.DUMMYFUNCTION("""COMPUTED_VALUE"""),"Belum disetujui") -> Belum disetujui
A27: =IFERROR(__xludf.DUMMYFUNCTION("""COMPUTED_VALUE"""),45992.83968498843) -> 45992.84 | B27: =IFERROR(__xludf.DUMMYFUNCTION("""COMPUTED_VALUE"""),"WINDRI MANOE") -> WINDRI MANOE | C27: =IFERROR(__xludf.DUMMYFUNCTION("""COMPUTED_VALUE"""),"Belum disetujui") -> Belum disetujui
A28: =IFERROR(__xludf.DUMMYFUNCTION("""COMPUTED_VALUE"""),45992.840489166665) -> 45992.84 | B28: =IFERROR(__xludf.DUMMYFUNCTION("""COMPUTED_VALUE"""),"WINDRI MANOE") -> WINDRI MANOE | C28: =IFERROR(__xludf.DUMMYFUNCTION("""COMPUTED_VALUE"""),"Belum disetujui") -> Belum disetujui
A29: =IFERROR(__xludf.DUMMYFUNCTION("""COMPUTED_VALUE"""),45992.85128471065) -> 45992.851 | B29: =IFERROR(__xludf.DUMMYFUNCTION("""COMPUTED_VALUE"""),"DWITNEY PRETY WANGGANDIMA") -> DWITNEY PRETY WANGGANDIMA | C29: =IFERROR(__xludf.DUMMYFUNCTION("""COMPUTED_VALUE"""),"Belum disetujui") -> Belum disetujui
A30: =IFERROR(__xludf.DUMMYFUNCTION("""COMPUTED_VALUE"""),45992.85280275463) -> 45992.853 | B30: =IFERROR(__xludf.DUMMYFUNCTION("""COMPUTED_VALUE"""),"DWITNEY PRETY WANGGANDIMA") -> DWITNEY PRETY WANGGANDIMA | C30: =IFERROR(__xludf.DUMMYFUNCTION("""COMPUTED_VALUE"""),"Belum disetujui") -> Belum disetujui
